Workbook

Sheet Hoja 2
A1: Nombre | B1: Tipo | C1: Texto de carta | D1: Quien la hizo | E1: Rareza | F1: Creacion | G1: Imagen | H1: Lore | I1: Glosario | J1: Comentarios internos | K1: Estado | L1: Efecto en el código | M1: Dificultad para agregarla | N1: Qué falta para agregarla
A2: Ying y Yang | B2: Beneficio | C2: En tu próximo combate, restás 1 a todas tus tiradas. En el combate siguiente, sumás 3 a todas tus tiradas. | D2: Fede | E2: Común | H2: Un mercader chino | K2: Implementada | L2: TwoPhaseFlat: -1 en el primer combate y +3 en el siguiente · alcance: este combate y el siguiente | M2: — | N2: Ya anda en el juego
A3: Twisted | B3: Beneficio | C3: Durante tu próximo combate, si tu rival usa una Bendición que suma un número fijo a una tirada, esa suma se convierte en una resta por el mismo valor. | D3: Fede | E3: Común | H3: El Bufon | K3: Implementada | L3: TwistRival: las sumas fijas del rival se convierten en restas · alcance: todo el próximo combate · la aplica el rival | M3: — | N3: Ya anda en el juego
A4: Justicia Divina | B4: Beneficio | C4: Durante tu próximo combate, en cada tirada gana quien obtiene el número más bajo. | D4: Fede | E4: Común | H4: El juez | K4: Implementada | L4: WinRule: en esa tirada gana el número más bajo · alcance: todo el próximo combate | M4: — | N4: Ya anda en el juego
A5: Redistribución de las riquezas | B5: Beneficio | C5: Durante tu próximo combate, en cada tirada gana quien obtiene el resultado más cercano a 10. | D5: Fede | E5: Común | H5: El economista | K5: Implementada | L5: WinRule: gana el más cercano a 10 · alcance: todo el próximo combate | M5: — | N5: Ya anda en el juego
A6: Multiplicar | B6: Beneficio | C6: En tu próximo lanzamiento, duplicás el resultado. El resultado final no puede superar 20. | D6: Fede | E6: Común | H6: El matematico | K6: Implementada | L6: MultiplyCapped: multiplica x2 con tope 20 · alcance: próxima tirada | M6: — | N6: Ya anda en el juego
A7: Juego Seguro | B7: Beneficio | C7: En tu próximo lanzamiento, si sacás entre 1 y 9, triplicás el resultado. Si sacás entre 11 y 20, dividís el resultado entre 2 y redondeás hacia arriba. Si sacás 10, no cambia. | D7: Fede | E7: Común | H7: El matematico | K7: Implementada | L7: SafePlay: hasta 9 multiplica x3; desde 11 divide entre 2 · alcance: próxima tirada | M7: — | N7: Ya anda en el juego
A8: Trampa de oso | B8: Beneficio | C8: Durante tu próximo combate, una tirada del rival solo puede ganar si obtiene al menos 10. | D8: Fede | E8: Común | K8: Implementada | L8: WinRule: la tirada del rival solo gana con 10 o más · alcance: todo el próximo combate | M8: — | N8: Ya anda en el juego
A9: Trampa de oso + | B9: Beneficio | C9: Durante tu próximo combate, una tirada del rival solo puede ganar si obtiene al menos 15. | D9: Fede | E9: Común | K9: Implementada | L9: WinRule: la tirada del rival solo gana con 15 o más · alcance: todo el próximo combate | M9: — | N9: Ya anda en el juego
A10: Dos caminos | B10: Beneficio | C10: En tu próximo lanzamiento, si el resultado es impar, sumás 3. Si es par, restás 3. | D10: Fede | E10: Común | K10: Implementada | L10: ParityBonus: si sale impar: +3; si sale par: -3 · alcance: próxima tirada | M10: — | N10: Ya anda en el juego
A11: Dos caminos | B11: Beneficio | C11: En tu próximo lanzamiento, si el resultado es par, sumás 3. Si es impar, restás 3. | D11: Fede | E11: Común | K11: Implementada | L11: ParityBonus: si sale par: +3; si sale impar: -3 · alcance: próxima tirada | M11: — | N11: Ya anda en el juego
A12: Fibonacci | B12: Beneficio | C12: En tu próximo lanzamiento, si sacás un número de Fibonacci (1, 2, 3, 5, 8 o 13), sumás el número anterior de la secuencia. Los demás resultados no cambian. | D12: Fede | E12: Común | K12: Implementada | L12: FibonacciBonus: suma el Fibonacci anterior · alcance: próxima tirada | M12: — | N12: Ya anda en el juego
A13: No tan rápido +++ | B13: Beneficio | C13: En el próximo lanzamiento de tu rival, cualquier resultado mayor a 15 se convierte en 15. | D13: Fede | E13: Común | K13: Implementada | L13: MaxResult: el resultado no pasa de 15 · alcance: próxima tirada de combate · la aplica el rival | M13: — | N13: Ya anda en el juego
A14: No tan rápido | B14: Beneficio | C14: En el próximo lanzamiento de tu rival, restale 3 al resultado final. | D14: Fede | E14: Común | K14: Implementada | L14: FlatBonus: suma fija -3 · alcance: próxima tirada de combate · la aplica el rival | M14: — | N14: Ya anda en el juego
A15: Remordimiento | B15: Beneficio | C15: Robá una Bendición al azar de otro jugador. | D15: Fede | E15: Común | K15: Implementada | L15: HandAction: roba una bendición al azar de otro jugador · alcance: al recibirla | M15: — | N15: Ya anda en el juego
A16: Yang y Ying | B16: Maleficio | C16: En tu próximo combate, sumás 1 a todas tus tiradas. En el combate siguiente, restás 3 a todas tus tiradas. | D16: Fede | E16: Común | H16: Un mercader chino | K16: Implementada | L16: TwoPhaseFlat: +1 en el primer combate y -3 en el siguiente · alcance: este combate y el siguiente | M16: — | N16: Ya anda en el juego
A17: Condena | B17: Maleficio | C17: A partir de ahora, cada rival contra el que combatas recibe +1 a todas sus tiradas durante ese combate. | D17: Fede | E17: Común | H17: El DIablo | K17: Implementada | L17: FlatBonus: suma fija +1 · alcance: permanente · la aplica el rival | M17: — | N17: Ya anda en el juego
A18: Condena + | B18: Maleficio | C18: A partir de ahora, cada rival contra el que combatas recibe +2 a todas sus tiradas durante ese combate. | D18: Fede | E18: Común | H18: El DIablo | K18: Implementada | L18: FlatBonus: suma fija +2 · alcance: permanente · la aplica el rival | M18: — | N18: Ya anda en el juego
A19: Condena ++ | B19: Maleficio | C19: A partir de ahora, cada rival contra el que combatas recibe +3 a todas sus tiradas durante ese combate. | D19: Fede | E19: Común | H19: El DIablo | K19: Implementada | L19: FlatBonus: suma fija +3 · alcance: permanente · la aplica el rival | M19: — | N19: Ya anda en el juego
A20: Ying y Yang ++ | B20: Beneficio | C20: En tu próximo combate, restás 5 a todas tus tiradas. En el combate siguiente, sumás 10 a todas tus tiradas. | D20: Fede | E20: Épica | H20: Un mercader chino | K20: Implementada | L20: TwoPhaseFlat: -5 en el primer combate y +10 en el siguiente · alcance: este combate y el siguiente | M20: — | N20: Ya anda en el juego
A21: Twisted ++ | B21: Beneficio | C21: Durante tu próximo combate, si tu rival usa una Bendición que suma un número fijo a una tirada, esa suma no tiene efecto. | D21: Fede | E21: Épica | H21: El Bufon | K21: Implementada | L21: TwistRival: las sumas fijas del rival no tienen efecto · alcance: todo el próximo combate · la aplica el rival | M21: — | N21: Ya anda en el juego
A22: Dado Cambiado 5 + + | B22: Beneficio | C22: En tu próximo lanzamiento, tenés 5 tiradas en total. Convertí cada resultado del D20 a un valor de 1 a 5: 1-4 = 1, 5-8 = 2, 9-12 = 3, 13-16 = 4 y 17-20 = 5. Elegí uno de los cinco resultados. | D22: Fede | E22: Épica | H22: El Ingeniero | K22: Implementada | L22: DiceControl: tirás 5 dados convertidos a 1-5 y elegís · alcance: próxima tirada | M22: — | N22: Ya anda en el juego
A23: Fortuna + | B23: Beneficio | C23: A partir de ahora, en cada lanzamiento tirás 3 veces el D20 y elegís uno de los resultados. | D23: Fede | E23: Épica | H23: El Ingeniero | K23: Implementada | L23: DiceControl: tirás 3 dados y elegís · alcance: permanente | M23: — | N23: Ya anda en el juego
A24: Dos caminos + + | B24: Beneficio | C24: En tu próximo lanzamiento, si el resultado es impar, sumás 10. Si es par, restás 10. | D24: Fede | E24: Épica | K24: Implementada | L24: ParityBonus: si sale impar: +10; si sale par: -10 · alcance: próxima tirada | M24: — | N24: Ya anda en el juego
A25: Dos caminos + + | B25: Beneficio | C25: En tu próximo lanzamiento, si el resultado es par, sumás 10. Si es impar, restás 10. | D25: Fede | E25: Épica | K25: Implementada | L25: ParityBonus: si sale par: +10; si sale impar: -10 · alcance: próxima tirada | M25: — | N25: Ya anda en el juego
A26: Fibonacci Riesgoso | B26: Beneficio | C26: En tu próximo lanzamiento, si sacás un número de Fibonacci (1, 2, 3, 5, 8 o 13), sumás los dos números anteriores de la secuencia. Si no es Fibonacci, restás el número de Fibonacci anterior más cercano. | D26: Fede | E26: Épica | K26: Implementada | L26: FibonacciBonus: suma los dos anteriores; si no es Fibonacci, resta el anterior · alcance: próxima tirada | M26: — | N26: Ya anda en el juego
A27: No tan rápido ++ | B27: Beneficio | C27: En el próximo lanzamiento de tu rival, restale 10 al resultado final. | D27: Fede | E27: Épica | K27: Implementada | L27: FlatBonus: suma fija -10 · alcance: próxima tirada de combate · la aplica el rival | M27: — | N27: Ya anda en el juego
A28: Yang y Ying -- | B28: Maleficio | C28: En tu próximo combate, sumás 5 a todas tus tiradas. En el combate siguiente, restás 10 a todas tus tiradas. | D28: Fede | E28: Épica | H28: Un mercader chino | K28: Implementada | L28: TwoPhaseFlat: +5 en el primer combate y -10 en el siguiente · alcance: este combate y el siguiente | M28: — | N28: Ya anda en el juego
A29: Dado Cambiado 5 - - | B29: Maleficio | C29: En tu próximo lanzamiento, tenés 2 tiradas en total. Convertí cada resultado del D20 a 1-5: 1-4 = 1, 5-8 = 2, 9-12 = 3, 13-16 = 4 y 17-20 = 5. Elegí uno de los dos resultados. | D29: Fede | E29: Épica | H29: El Ingeniero | K29: Implementada | L29: DiceControl: tirás 2 dados convertidos a 1-5 y elegís · alcance: próxima tirada | M29: — | N29: Ya anda en el juego
A30: Mala suerte | B30: Maleficio | C30: En tu próximo combate, tu cantidad total de tiradas se reduce en 1. Nunca podés quedar con menos de 1 tirada. | D30: Fede | E30: Épica | H30: El Ingeniero | K30: Implementada | L30: CombatRolls: el combate dura 1 tirada menos · alcance: todo el próximo combate | M30: — | N30: Ya anda en el juego
A31: Dividir - | B31: Maleficio | C31: En tu próximo lanzamiento, dividí el resultado entre 2 y redondeá hacia arriba. Este efecto dura tus próximos 2 turnos. | D31: Fede | E31: Épica | H31: El matematico | K31: Implementada | L31: DivideRoundUp: divide entre 2 y redondea hacia arriba · alcance: próxima tirada · 2 uso(s) | M31: — | N31: Ya anda en el juego
A32: Ying y Yang + | B32: Beneficio | C32: En tu próximo combate, restás 3 a todas tus tiradas. En el combate siguiente, sumás 5 a todas tus tiradas. | D32: Fede | E32: Peligrosa | H32: Un mercader chino | K32: Implementada | L32: TwoPhaseFlat: -3 en el primer combate y +5 en el siguiente · alcance: este combate y el siguiente | M32: — | N32: Ya anda en el juego
A33: Twisted + | B33: Beneficio | C33: En tu próximo combate, si tu rival usa una Bendición que multiplica una tirada, el resultado se divide en lugar de multiplicarse. | D33: Fede | E33: Peligrosa | H33: El Bufon | K33: Implementada | L33: TwistRival: lo que el rival multiplica, se divide · alcance: todo el próximo combate · la aplica el rival | M33: — | N33: Ya anda en el juego
A34: Dado Cambiado 2 + | B34: Beneficio | C34: En tu próximo lanzamiento, tenés 3 tiradas en total. Convertí cada resultado del D20 a 1 o 2: 1-10 = 1 y 11-20 = 2. Elegí uno de los tres resultados. | D34: Fede | E34: Peligrosa | H34: El Ingeniero | K34: Implementada | L34: DiceControl: tirás 3 dados convertidos a 1-2 y elegís · alcance: próxima tirada | M34: — | N34: Ya anda en el juego
A35: Dado Cambiado 5 + | B35: Beneficio | C35: En tu próximo lanzamiento, tenés 4 tiradas en total. Convertí cada resultado del D20 a 1-5: 1-4 = 1, 5-8 = 2, 9-12 = 3, 13-16 = 4 y 17-20 = 5. Elegí uno de los cuatro resultados. | D35: Fede | E35: Peligrosa | H35: El Ingeniero | K35: Implementada | L35: DiceControl: tirás 4 dados convertidos a 1-5 y elegís · alcance: próxima tirada | M35: — | N35: Ya anda en el juego
A36: Fortuna | B36: Beneficio | C36: A partir de ahora, en cada lanzamiento tirás 2 veces el D20 y elegís uno de los resultados. | D36: Fede | E36: Peligrosa | H36: El Ingeniero | K36: Implementada | L36: DiceControl: tirás 2 dados y elegís · alcance: permanente | M36: — | N36: Ya anda en el juego
A37: Multiplicar + | B37: Beneficio | C37: En tu próximo lanzamiento, duplicás el resultado. El resultado final no puede superar 25. | D37: Fede | E37: Peligrosa | H37: El matematico | K37: Implementada | L37: MultiplyCapped: multiplica x2 con tope 25 · alcance: próxima tirada | M37: — | N37: Ya anda en el juego
A38: Multiplicar ++ | B38: Beneficio | C38: En tu próximo lanzamiento, duplicás el resultado. El resultado final no puede superar 30. | D38: Fede | E38: Peligrosa | H38: El matematico | K38: Implementada | L38: MultiplyCapped: multiplica x2 con tope 30 · alcance: próxima tirada | M38: — | N38: Ya anda en el juego
A39: El apostador | B39: Beneficio | C39: En tu próximo lanzamiento, tirás el D20 una segunda vez y lanzás una moneda. Si sale cara, dividís el segundo resultado entre 2 y redondeás hacia arriba. Si sale cruz, duplicás el segundo resultado. | D39: Fede | E39: Peligrosa | H39: Dueño del casino | K39: Implementada | L39: DiceControl: segunda tirada con moneda: mitad o doble · alcance: próxima tirada | M39: — | N39: Ya anda en el juego
A40: Dos caminos + | B40: Beneficio | C40: En tu próximo lanzamiento, si el resultado es impar, sumás 5. Si es par, restás 5. | D40: Fede | E40: Peligrosa | K40: Implementada | L40: ParityBonus: si sale impar: +5; si sale par: -5 · alcance: próxima tirada | M40: — | N40: Ya anda en el juego
...

Sheet Resumen
A1: Tipo | B1: Rareza | C1: Cantidad | D1: Objetivo | F1: Color | G1: Rareza | H1: Implementadas | I1: Pendientes | J1: % hecho
A2: Beneficio | B2: Común | C2: 16 | D2: 16 | F2: Gris | G2: Común | H2: =COUNTIFS('Hoja 2'!$B$2:$B$97,$A2,'Hoja 2'!$E$2:$E$97,$B2,'Hoja 2'!$K$2:$K$97,"Implementada") -> 16 | I2: =COUNTIFS('Hoja 2'!$B$2:$B$97,$A2,'Hoja 2'!$E$2:$E$97,$B2,'Hoja 2'!$K$2:$K$97,"Pendiente") -> 0 | J2: =IFERROR(H2/C2,"") -> 1
A3: Beneficio | B3: Peligrosa | C3: 16 | D3: 16 | F3: Rojo | G3: Peligrosa | H3: =COUNTIFS('Hoja 2'!$B$2:$B$97,$A3,'Hoja 2'!$E$2:$E$97,$B3,'Hoja 2'!$K$2:$K$97,"Implementada") -> 16 | I3: =COUNTIFS('Hoja 2'!$B$2:$B$97,$A3,'Hoja 2'!$E$2:$E$97,$B3,'Hoja 2'!$K$2:$K$97,"Pendiente") -> 0 | J3: =IFERROR(H3/C3,"") -> 1
A4: Beneficio | B4: Épica | C4: 16 | D4: 16 | F4: Morado | G4: Épica | H4: =COUNTIFS('Hoja 2'!$B$2:$B$97,$A4,'Hoja 2'!$E$2:$E$97,$B4,'Hoja 2'!$K$2:$K$97,"Implementada") -> 16 | I4: =COUNTIFS('Hoja 2'!$B$2:$B$97,$A4,'Hoja 2'!$E$2:$E$97,$B4,'Hoja 2'!$K$2:$K$97,"Pendiente") -> 0 | J4: =IFERROR(H4/C4,"") -> 1
A5: Maleficio | B5: Común | C5: 16 | D5: 16 | H5: =COUNTIFS('Hoja 2'!$B$2:$B$97,$A5,'Hoja 2'!$E$2:$E$97,$B5,'Hoja 2'!$K$2:$K$97,"Implementada") -> 16 | I5: =COUNTIFS('Hoja 2'!$B$2:$B$97,$A5,'Hoja 2'!$E$2:$E$97,$B5,'Hoja 2'!$K$2:$K$97,"Pendiente") -> 0 | J5: =IFERROR(H5/C5,"") -> 1
A6: Maleficio | B6: Peligrosa | C6: 16 | D6: 16 | H6: =COUNTIFS('Hoja 2'!$B$2:$B$97,$A6,'Hoja 2'!$E$2:$E$97,$B6,'Hoja 2'!$K$2:$K$97,"Implementada") -> 16 | I6: =COUNTIFS('Hoja 2'!$B$2:$B$97,$A6,'Hoja 2'!$E$2:$E$97,$B6,'Hoja 2'!$K$2:$K$97,"Pendiente") -> 0 | J6: =IFERROR(H6/C6,"") -> 1
A7: Maleficio | B7: Épica | C7: 16 | D7: 16 | H7: =COUNTIFS('Hoja 2'!$B$2:$B$97,$A7,'Hoja 2'!$E$2:$E$97,$B7,'Hoja 2'!$K$2:$K$97,"Implementada") -> 16 | I7: =COUNTIFS('Hoja 2'!$B$2:$B$97,$A7,'Hoja 2'!$E$2:$E$97,$B7,'Hoja 2'!$K$2:$K$97,"Pendiente") -> 0 | J7: =IFERROR(H7/C7,"") -> 1
A8: TOTAL | C8: =SUM(C2:C7) -> 96 | D8: =SUM(D2:D7) -> 96 | H8: =SUM(H2:H7) -> 96 | I8: =SUM(I2:I7) -> 0 | J8: =IFERROR(H8/C8,"") -> 1
A16: Cómo leer las columnas nuevas de la hoja "Hoja 2"
A17: Estado: las 96 cartas están implementadas en el prototipo de C++/raylib.
A18: Efecto en el código: el tipo de efecto y los parámetros con los que está cargada en src/Cards.cpp.
A19: El motor que las aplica está en src/Effects.cpp; el orden de resolución está explicado en el README.
A21: Las columnas A-J son las originales del Excel del grupo, sin tocar.
